Workbook

Sheet Master Ratings
A1: 2026 Synthetic CFB Preseason Ratings Master — Unified Ensemble
A2: Separate source ratings plus a governed four-family unified preseason power rating: 25% TrueSkill, 25% Litkenhous, 25% Pure Baxter, and 25% Board family (12.5% Board I-H + 12.5% Board J-B).
A4: Conference | B4: Team | C4: Short | D4: Master Team ID | E4: Schedule ID | F4: TrueSkill 2026 Preseason μ | G4: TrueSkill Rank | H4: TrueSkill σ | I4: TrueSkill μ−3σ | J4: TrueSkill Carryover Status | K4: TrueSkill Prior Method | L4: Litkenhous Adjusted Power | M4: Litkenhous Adjusted Rating | N4: Litkenhous Adjusted Rank | O4: Litkenhous Offseason Composite | P4: Litkenhous Offseason Adjustment | Q4: Litkenhous Evidence Status | R4: Reconciliation | S4: Board I-H Power Rating (power_H) | T4: Board I-H Power Rank (rank_H) | U4: Board I-H Committee Rating (committee_H) | V4: Board I-H Committee Rank (rank_I) | W4: Board J-B Run2 Power Rating (power_Run2) | X4: Board J-B Run2 Power Rank (rank_Run2) | Y4: Board J-B Run2 Committee Rating (committee_Run2) | Z4: Board J-B Run2 Committee Rank (rank_I) | AA4: Board J-B Baseline | AB4: Board J-B Returning | AC4: Board J-B Movement | AD4: Board J-B Talent | AE4: Board J-B Coaching | AF4: Board J-B Market | AG4: Board J-B 247 Points | AH4: Board J-B Rank Shift | AI4: Board J-B Source Status | AJ4: Board J-A Expected Wins | AK4: Board J-B Expected Wins | AL4: Board J-C Expected Wins | AM4: 2025 Baxter Ridge Rating | AN4: 2025 Baxter Rank | AO4: 2025 Baxter Games | AP4: Baxter Carryforward Status | AQ4: 2026 Pure Baxter Rating | AR4: 2026 Pure Baxter Rank | AS4: Baxter Offseason Adjustment | AT4: 2026 Enhanced Baxter Rating | AU4: 2026 Enhanced Baxter Rank | AV4: SP+ Rating | AW4: SP+ Build Status | AX4: SP+ Blocking Evidence | AY4: Billingsley Seed Power | AZ4: Billingsley Seed Rating | BA4: Billingsley Seed Rank | BB4: Billingsley Uncertainty | BC4: Billingsley Active Rating | BD4: Billingsley Active Rank | BE4: Billingsley Build Status | BF4: Markov Schedule PageRank | BG4: Markov Topology Rank | BH4: Markov Scheduled Games | BI4: Markov Unique In-Field Opponents | BJ4: Markov Out-of-Field Games | BK4: Markov Performance Rating | BL4: Markov Build Status | BM4: TrueSkill Z | BN4: Litkenhous Z | BO4: Board I-H Z | BP4: Board J-B Z | BQ4: Board Family Z | BR4: Pure Baxter Z | BS4: Unified Master Z | BT4: Unified Master Power Index | BU4: Unified Neutral-Field Points | BV4: Unified Master Rank | BW4: Family Disagreement | BX4: Confidence Grade | BY4: Review Flag | BZ4: Included Family Count
A5: ACC | B5: Boston College | C5: BC | D5: 51 | E5: BC | F5: 21.002956 | G5: 106 | H5: 4.2785774 | I5: 8.1672237 | J5: 2025_POSTERIOR_CARRYOVER | K5: P0_REGRESSED_2025_POSTERIOR | L5: -4.2089536 | M5: 95.791046 | N5: 78 | O5: 0.57669524 | P5: 1.2271238 | Q5: Complete | R5: PASS | S5: 0.417909 | T5: 81 | U5: 0.402752 | V5: 75 | W5: 0.44355 | X5: 77 | Y5: 0.42611442 | Z5: 75 | AA5: 0.2095 | AB5: 0.586 | AC5: 0.4621 | AD5: 0.525 | AE5: 0.85 | AF5: 0.2474 | AG5: 14.38 | AH5: -5 | AI5: AVAILABLE — exact from 2026_Board_J-B_Run2.xlsx | AJ5: 3.91 | AK5: 4.16 | AL5: 5.02 | AM5: -10.830666 | AN5: 77 | AO5: 12 | AP5: 2025 Baxter fitted rating | AQ5: -7.5814663 | AR5: 79 | AS5: 0.99058335 | AT5: -6.590883 | AU5: 72 | AW5: BLOCKED | AX5: No play-by-play/drive efficiency, scoring-opportunity, explosiveness, field-position, havoc, or special-teams results; official SP+ coefficients are unavailable. | AY5: -6.287499 | AZ5: 93.712501 | BA5: 83 | BB5: B | BE5: INITIALIZATION ONLY | BF5: 0.0082813064 | BG5: 73 | BH5: 12 | BI5: 12 | BJ5: 0 | BL5: PARTIAL — TOPOLOGY ONLY | BM5: =(F5-'Ensemble Parameters'!$B$20)/'Ensemble Parameters'!$C$20 -> -0.95117975 | BN5: =(L5-'Ensemble Parameters'!$B$21)/'Ensemble Parameters'!$C$21 -> -0.44118647 | BO5: =(S5-'Ensemble Parameters'!$B$22)/'Ensemble Parameters'!$C$22 -> -0.41853606 | BP5: =(W5-'Ensemble Parameters'!$B$23)/'Ensemble Parameters'!$C$23 -> -0.35277458 | BQ5: =AVERAGE(BO5:BP5) -> -0.38565532 | BR5: =(AQ5-'Ensemble Parameters'!$B$24)/'Ensemble Parameters'!$C$24 -> -0.49737778 | BS5: =BM5*'Ensemble Parameters'!$B$5+BN5*'Ensemble Parameters'!$B$6+BQ5*'Ensemble Parameters'!$B$8+BR5*'Ensemble Parameters'!$B$7 -> -0.56884983 | BT5: ='Ensemble Parameters'!$B$11+'Ensemble Parameters'!$B$12*BS5 -> 94.311502 | BU5: ='Ensemble Parameters'!$B$13*BS5 -> -7.9638976 | BV5: =RANK(BT5,$BT$5:$BT$125,0) -> 79 | BW5: =STDEV(BM5,BN5,BQ5,BR5) -> 0.25893537 | BX5: =IF(BW5<'Ensemble Parameters'!$B$14,"High",IF(BW5<'Ensemble Parameters'!$B$15,"Moderate","Low")) -> High | BY5: =IF(BX5="Low","REVIEW — MODEL DISAGREEMENT","") | BZ5: 4
A6: ACC | B6: California | C6: CAL | D6: 52 | E6: CAL | F6: 23.196593 | G6: 69 | H6: 4.1296154 | I6: 10.807747 | J6: 2025_POSTERIOR_CARRYOVER | K6: P0_REGRESSED_2025_POSTERIOR | L6: -2.2499853 | M6: 97.750015 | N6: 54 | O6: 0.585 | P6: 1.36 | Q6: Complete | R6: PASS | S6: 0.470444 | T6: 49 | U6: 0.474849 | V6: 45 | W6: 0.484065 | X6: 49 | Y6: 0.48725923 | Z6: 45 | AA6: 0.3201 | AB6: 0.6464 | AC6: 0.5678 | AD6: 0.683 | AE6: 0.325 | AF6: 0.52 | AG6: 43.04 | AH6: -4 | AI6: AVAILABLE — exact from 2026_Board_J-B_Run2.xlsx | AJ6: 5.88 | AK6: 5.91 | AL6: 5.01 | AM6: -8.9172489 | AN6: 63 | AO6: 12 | AP6: 2025 Baxter fitted rating | AQ6: -6.2420742 | AR6: 65 | AS6: 0.62865996 | AT6: -5.6134143 | AU6: 61 | AW6: BLOCKED | AX6: No play-by-play/drive efficiency, scoring-opportunity, explosiveness, field-position, havoc, or special-teams results; official SP+ coefficients are unavailable. | AY6: -2.1477308 | AZ6: 97.852269 | BA6: 55 | BB6: B | BE6: INITIALIZATION ONLY | BF6: 0.0082851503 | BG6: 66 | BH6: 12 | BI6: 12 | BJ6: 0 | BL6: PARTIAL — TOPOLOGY ONLY | BM6: =(F6-'Ensemble Parameters'!$B$20)/'Ensemble Parameters'!$C$20 -> -0.44796989 | BN6: =(L6-'Ensemble Parameters'!$B$21)/'Ensemble Parameters'!$C$21 -> -0.23584557 | BO6: =(S6-'Ensemble Parameters'!$B$22)/'Ensemble Parameters'!$C$22 -> -0.052176007 | BP6: =(W6-'Ensemble Parameters'!$B$23)/'Ensemble Parameters'!$C$23 -> -0.035320035 | BQ6: =AVERAGE(BO6:BP6) -> -0.043748021 | BR6: =(AQ6-'Ensemble Parameters'!$B$24)/'Ensemble Parameters'!$C$24 -> -0.4085044 | BS6: =BM6*'Ensemble Parameters'!$B$5+BN6*'Ensemble Parameters'!$B$6+BQ6*'Ensemble Parameters'!$B$8+BR6*'Ensemble Parameters'!$B$7 -> -0.28401697 | BT6: ='Ensemble Parameters'!$B$11+'Ensemble Parameters'!$B$12*BS6 -> 97.15983 | BU6: ='Ensemble Parameters'!$B$13*BS6 -> -3.9762376 | BV6: =RANK(BT6,$BT$5:$BT$125,0) -> 57 | BW6: =STDEV(BM6,BN6,BQ6,BR6) -> 0.18477674 | BX6: =IF(BW6<'Ensemble Parameters'!$B$14,"High",IF(BW6<'Ensemble Parameters'!$B$15,"Moderate","Low")) -> High | BY6: =IF(BX6="Low","REVIEW — MODEL DISAGREEMENT","") | BZ6: 4
A7: ACC | B7: Clemson | C7: CLEM | D7: 53 | E7: CLEM | F7: 22.980487 | G7: 71 | H7: 4.1745285 | I7: 10.456901 | J7: 2025_POSTERIOR_CARRYOVER | K7: P0_REGRESSED_2025_POSTERIOR | L7: -2.8045998 | M7: 97.1954 | N7: 60 | O7: 0.60282857 | P7: 1.6452571 | Q7: Complete | R7: PASS | S7: 0.455349 | T7: 51 | U7: 0.466358 | V7: 56 | W7: 0.476615 | X7: 50 | Y7: 0.48573368 | Z7: 56 | AA7: 0.2618 | AB7: 0.4673 | AC7: 0.4725 | AD7: 0.884 | AE7: 0.85 | AF7: 0.5792 | AG7: 16.51 | AH7: 5 | AI7: AVAILABLE — exact from 2026_Board_J-B_Run2.xlsx | AJ7: 5.25 | AK7: 5.33 | AL7: 5.67 | AM7: -10.779765 | AN7: 75 | AO7: 12 | AP7: 2025 Baxter fitted rating | AQ7: -7.5458358 | AR7: 77 | AS7: 1.1476894 | AT7: -6.3981464 | AU7: 69 | AW7: BLOCKED | AX7: No play-by-play/drive efficiency, scoring-opportunity, explosiveness, field-position, havoc, or special-teams results; official SP+ coefficients are unavailable. | AY7: -2.2287453 | AZ7: 97.771255 | BA7: 56 | BB7: B | BE7: INITIALIZATION ONLY | BF7: 0.0082738497 | BG7: 86 | BH7: 12 | BI7: 12 | BJ7: 0 | BL7: PARTIAL — TOPOLOGY ONLY | BM7: =(F7-'Ensemble Parameters'!$B$20)/'Ensemble Parameters'!$C$20 -> -0.49754362 | BN7: =(L7-'Ensemble Parameters'!$B$21)/'Ensemble Parameters'!$C$21 -> -0.29398079 | BO7: =(S7-'Ensemble Parameters'!$B$22)/'Ensemble Parameters'!$C$22 -> -0.15744307 | BP7: =(W7-'Ensemble Parameters'!$B$23)/'Ensemble Parameters'!$C$23 -> -0.093694375 | BQ7: =AVERAGE(BO7:BP7) -> -0.12556872 | BR7: =(AQ7-'Ensemble Parameters'!$B$24)/'Ensemble Parameters'!$C$24 -> -0.49501357 | BS7: =BM7*'Ensemble Parameters'!$B$5+BN7*'Ensemble Parameters'!$B$6+BQ7*'Ensemble Parameters'!$B$8+BR7*'Ensemble Parameters'!$B$7 -> -0.35302668 | BT7: ='Ensemble Parameters'!$B$11+'Ensemble Parameters'!$B$12*BS7 -> 96.469733 | BU7: ='Ensemble Parameters'!$B$13*BS7 -> -4.9423735 | BV7: =RANK(BT7,$BT$5:$BT$125,0) -> 65 | BW7: =STDEV(BM7,BN7,BQ7,BR7) -> 0.17913586 | BX7: =IF(BW7<'Ensemble Parameters'!$B$14,"High",IF(BW7<'Ensemble Parameters'!$B$15,"Moderate","Low")) -> High | BY7: =IF(BX7="Low","REVIEW — MODEL DISAGREEMENT","") | BZ7: 4
A8: ACC | B8: Duke | C8: DUKE | D8: 54 | E8: DUKE | F8: 26.563778 | G8: 38 | H8: 3.9405825 | I8: 14.74203 | J8: 2025_POSTERIOR_CARRYOVER | K8: P0_REGRESSED_2025_POSTERIOR | L8: 0.079385523 | M8: 100.07939 | N8: 43 | O8: 0.55368571 | P8: 0.85897143 | Q8: Complete | R8: PASS | S8: 0.516025 | T8: 40 | U8: 0.510583 | V8: 41 | W8: 0.525065 | X8: 41 | Y8: 0.51881921 | Z8: 41 | AA8: 0.4666 | AB8: 0.4429 | AC8: 0.4607 | AD8: 0.58 | AE8: 1 | AF8: 0.4548 | AG8: 14.1 | AH8: 1 | AI8: AVAILABLE — exact from 2026_Board_J-B_Run2.xlsx | AJ8: 5.72 | AK8: 5.82 | AL8: 6.32 | AM8: -3.164755 | AN8: 45 | AO8: 13 | AP8: 2025 Baxter fitted rating | AQ8: -2.2153285 | AR8: 45 | AS8: -0.14970932 | AT8: -2.3650378 | AU8: 46 | AW8: BLOCKED | AX8: No play-by-play/drive efficiency, scoring-opportunity, explosiveness, field-position, havoc, or special-teams results; official SP+ coefficients are unavailable. | AY8: -0.33995993 | AZ8: 99.66004 | BA8: 42 | BB8: B | BE8: INITIALIZATION ONLY | BF8: 0.0082803034 | BG8: 76 | BH8: 12 | BI8: 12 | BJ8: 0 | BL8: PARTIAL — TOPOLOGY ONLY | BM8: =(F8-'Ensemble Parameters'!$B$20)/'Ensemble Parameters'!$C$20 -> 0.32444636 | BN8: =(L8-'Ensemble Parameters'!$B$21)/'Ensemble Parameters'!$C$21 -> 0.0083212651 | BO8: =(S8-'Ensemble Parameters'!$B$22)/'Ensemble Parameters'!$C$22 -> 0.26568937 | BP8: =(W8-'Ensemble Parameters'!$B$23)/'Ensemble Parameters'!$C$23 -> 0.28593472 | BQ8: =AVERAGE(BO8:BP8) -> 0.27581204 | BR8: =(AQ8-'Ensemble Parameters'!$B$24)/'Ensemble Parameters'!$C$24 -> -0.14131564 | BS8: =BM8*'Ensemble Parameters'!$B$5+BN8*'Ensemble Parameters'!$B$6+BQ8*'Ensemble Parameters'!$B$8+BR8*'Ensemble Parameters'!$B$7 -> 0.11681601 | BT8: ='Ensemble Parameters'!$B$11+'Ensemble Parameters'!$B$12*BS8 -> 101.16816 | BU8: ='Ensemble Parameters'!$B$13*BS8 -> 1.6354241 | BV8: =RANK(BT8,$BT$5:$BT$125,0) -> 39 | BW8: =STDEV(BM8,BN8,BQ8,BR8) -> 0.22120365 | BX8: =IF(BW8<'Ensemble Parameters'!$B$14,"High",IF(BW8<'Ensemble Parameters'!$B$15,"Moderate","Low")) -> High | BY8: =IF(BX8="Low","REVIEW — MODEL DISAGREEMENT","") | BZ8: 4
A9: ACC | B9: Florida State | C9: FSU | D9: 55 | E9: FSU | F9: 24.009661 | G9: 57 | H9: 4.2561821 | I9: 11.241115 | J9: 2025_POSTERIOR_CARRYOVER | K9: P0_REGRESSED_2025_POSTERIOR | L9: -4.1181264 | M9: 95.881874 | N9: 76 | O9: 0.61754286 | P9: 1.8806857 | Q9: Complete | R9: PASS | S9: 0.476502 | T9: 48 | U9: 0.478297 | V9: 47 | W9: 0.50097 | X9: 45 | Y9: 0.50059044 | Z9: 47 | AA9: 0.2914 | AB9: 0.5054 | AC9: 0.5352 | AD9: 0.791 | AE9: 0.85 | AF9: 0.4967 | AG9: 32.56 | AH9: -1 | AI9: AVAILABLE — exact from 2026_Board_J-B_Run2.xlsx | AJ9: 4.67 | AK9: 4.99 | AL9: 5.41 | AM9: -15.09152 | AN9: 88 | AO9: 12 | AP9: 2025 Baxter fitted rating | AQ9: -10.564064 | AR9: 90 | AS9: 1.3697655 | AT9: -9.1942983 | AU9: 88 | AW9: BLOCKED | AX9: No play-by-play/drive efficiency, scoring-opportunity, explosiveness, field-position, havoc, or special-teams results; official SP+ coefficients are unavailable. | AY9: -4.2022718 | AZ9: 95.797728 | BA9: 72 | BB9: B | BE9: INITIALIZATION ONLY | BF9: 0.0082768246 | BG9: 82 | BH9: 12 | BI9: 12 | BJ9: 0 | BL9: PARTIAL — TOPOLOGY ONLY | BM9: =(F9-'Ensemble Parameters'!$B$20)/'Ensemble Parameters'!$C$20 -> -0.26145588 | BN9: =(L9-'Ensemble Parameters'!$B$21)/'Ensemble Parameters'!$C$21 -> -0.43166588 | BO9: =(S9-'Ensemble Parameters'!$B$22)/'Ensemble Parameters'!$C$22 -> -0.0099297107 | BP9: =(W9-'Ensemble Parameters'!$B$23)/'Ensemble Parameters'!$C$23 -> 0.097138785 | BQ9: =AVERAGE(BO9:BP9) -> 0.043604537 | BR9: =(AQ9-'Ensemble Parameters'!$B$24)/'Ensemble Parameters'!$C$24 -> -0.69528363 | BS9: =BM9*'Ensemble Parameters'!$B$5+BN9*'Ensemble Parameters'!$B$6+BQ9*'Ensemble Parameters'!$B$8+BR9*'Ensemble Parameters'!$B$7 -> -0.33620021 | BT9: ='Ensemble Parameters'!$B$11+'Ensemble Parameters'!$B$12*BS9 -> 96.637998 | BU9: ='Ensemble Parameters'!$B$13*BS9 -> -4.706803 | BV9: =RANK(BT9,$BT$5:$BT$125,0) -> 61 | BW9: =STDEV(BM9,BN9,BQ9,BR9) -> 0.30978108 | BX9: =IF(BW9<'Ensemble Parameters'!$B$14,"High",IF(BW9<'Ensemble Parameters'!$B$15,"Moderate","Low")) -> Moderate | BY9: =IF(BX9="Low","REVIEW — MODEL DISAGREEMENT","") | BZ9: 4
A10: ACC | B10: Georgia Tech | C10: GT | D10: 56 | E10: GT | F10: 29.586502 | G10: 24 | H10: 4.3246956 | I10: 16.612415 | J10: 2025_POSTERIOR_CARRYOVER | K10: P0_REGRESSED_2025_POSTERIOR | L10: 7.4447751 | M10: 107.44478 | N10: 27 | O10: 0.56855238 | P10: 1.0968381 | Q10: Complete | R10: PASS | S10: 0.605378 | T10: 26 | U10: 0.599353 | V10: 26 | W10: 0.600255 | X10: 26 | Y10: 0.59468566 | Z10: 26 | AA10: 0.6537 | AB10: 0.4513 | AC10: 0.5172 | AD10: 0.669 | AE10: 0.85 | AF10: 0.5376 | AG10: 27.42 | AH10: 0 | AI10: AVAILABLE — exact from 2026_Board_J-B_Run2.xlsx | AJ10: 7.72 | AK10: 7.5 | AL10: 6.89 | AM10: 14.548386 | AN10: 27 | AO10: 13 | AP10: 2025 Baxter fitted rating | AQ10: 10.18387 | AR10: 27 | AS10: -0.60496493 | AT10: 9.5789054 | AU10: 27 | AW10: BLOCKED | AX10: No play-by-play/drive efficiency, scoring-opportunity, explosiveness, field-position, havoc, or special-teams results; official SP+ coefficients are unavailable. | AY10: 7.6878297 | AZ10: 107.68783 | BA10: 27 | BB10: B | BE10: INITIALIZATION ONLY | BF10: 0.0082783085 | BG10: 78 | BH10: 12 | BI10: 12 | BJ10: 0 | BL10: PARTIAL — TOPOLOGY ONLY | BM10: =(F10-'Ensemble Parameters'!$B$20)/'Ensemble Parameters'!$C$20 -> 1.0178449 | BN10: =(L10-'Ensemble Parameters'!$B$21)/'Ensemble Parameters'!$C$21 -> 0.78036832 | BO10: =(S10-'Ensemble Parameters'!$B$22)/'Ensemble Parameters'!$C$22 -> 0.8888048 | BP10: =(W10-'Ensemble Parameters'!$B$23)/'Ensemble Parameters'!$C$23 -> 0.8750846 | BQ10: =AVERAGE(BO10:BP10) -> 0.8819447 | BR10: =(AQ10-'Ensemble Parameters'!$B$24)/'Ensemble Parameters'!$C$24 -> 0.68141486 | BS10: =BM10*'Ensemble Parameters'!$B$5+BN10*'Ensemble Parameters'!$B$6+BQ10*'Ensemble Parameters'!$B$8+BR10*'Ensemble Parameters'!$B$7 -> 0.84039319 | BT10: ='Ensemble Parameters'!$B$11+'Ensemble Parameters'!$B$12*BS10 -> 108.40393 | BU10: ='Ensemble Parameters'!$B$13*BS10 -> 11.765505 | BV10: =RANK(BT10,$BT$5:$BT$125,0) -> 25 | BW10: =STDEV(BM10,BN10,BQ10,BR10) -> 0.14386652 | BX10: =IF(BW10<'Ensemble Parameters'!$B$14,"High",IF(BW10<'Ensemble Parameters'!$B$15,"Moderate","Low")) -> High | BY10: =IF(BX10="Low","REVIEW — MODEL DISAGREEMENT","") | BZ10: 4
A11: ACC | B11: Louisville | C11: LOU | D11: 57 | E11: LOU | F11: 25.778788 | G11: 40 | H11: 4.0389825 | I11: 13.661841 | J11: 2025_POSTERIOR_CARRYOVER | K11: P0_REGRESSED_2025_POSTERIOR | L11: 2.9352047 | M11: 102.9352 | N11: 33 | O11: 0.5883619 | P11: 1.4137905 | Q11: Complete | R11: PASS | S11: 0.536788 | T11: 37 | U11: 0.543038 | V11: 33 | W11: 0.551205 | X11: 34 | Y11: 0.55617345 | Z11: 33 | AA11: 0.4691 | AB11: 0.4891 | AC11: 0.5688 | AD11: 0.62 | AE11: 0.85 | AF11: 0.6071 | AG11: 43.39 | AH11: -4 | AI11: AVAILABLE — exact from 2026_Board_J-B_Run2.xlsx | AJ11: 6.32 | AK11: 6.44 | AL11: 6.43 | AM11: 4.0087328 | AN11: 31 | AO11: 13 | AP11: 2025 Baxter fitted rating | AQ11: 2.8061129 | AR11: 31 | AS11: 0.43750648 | AT11: 3.2436194 | AU11: 31 | AW11: BLOCKED | AX11: No play-by-play/drive efficiency, scoring-opportunity, explosiveness, field-position, havoc, or special-teams results; official SP+ coefficients are unavailable. | AY11: 3.7342593 | AZ11: 103.73426 | BA11: 33 | BB11: B | BE11: INITIALIZATION ONLY | BF11: 0.0082658774 | BG11: 95 | BH11: 12 | BI11: 12 | BJ11: 0 | BL11: PARTIAL — TOPOLOGY ONLY | BM11: =(F11-'Ensemble Parameters'!$B$20)/'Ensemble Parameters'!$C$20 -> 0.14437352 | BN11: =(L11-'Ensemble Parameters'!$B$21)/'Ensemble Parameters'!$C$21 -> 0.30767092 | BO11: =(S11-'Ensemble Parameters'!$B$22)/'Ensemble Parameters'!$C$22 -> 0.410483 | BP11: =(W11-'Ensemble Parameters'!$B$23)/'Ensemble Parameters'!$C$23 -> 0.49075422 | BQ11: =AVERAGE(BO11:BP11) -> 0.45061861 | BR11: =(AQ11-'Ensemble Parameters'!$B$24)/'Ensemble Parameters'!$C$24 -> 0.19187468 | BS11: =BM11*'Ensemble Parameters'!$B$5+BN11*'Ensemble Parameters'!$B$6+BQ11*'Ensemble Parameters'!$B$8+BR11*'Ensemble Parameters'!$B$7 -> 0.27363443 | BT11: ='Ensemble Parameters'!$B$11+'Ensemble Parameters'!$B$12*BS11 -> 102.73634 | BU11: ='Ensemble Parameters'!$B$13*BS11 -> 3.8308821 | BV11: =RANK(BT11,$BT$5:$BT$125,0) -> 34 | BW11: =STDEV(BM11,BN11,BQ11,BR11) -> 0.13647334 | BX11: =IF(BW11<'Ensemble Parameters'!$B$14,"High",IF(BW11<'Ensemble Parameters'!$B$15,"Moderate","Low")) -> High | BY11: =IF(BX11="Low","REVIEW — MODEL DISAGREEMENT","") | BZ11: 4
A12: ACC | B12: Miami | C12: MIA | D12: 58 | E12: MIA | F12: 35.448411 | G12: 2 | H12: 4.1267581 | I12: 23.068137 | J12: 2025_POSTERIOR_CARRYOVER | K12: P0_REGRESSED_2025_POSTERIOR | L12: 21.388067 | M12: 121.38807 | N12: 3 | O12: 0.64770476 | P12: 2.3632762 | Q12: Complete | R12: PASS | S12: 0.796767 | T12: 3 | U12: 0.802912 | V12: 3 | W12: 0.771735 | X12: 3 | Y12: 0.78010523 | Z12: 3 | AA12: 0.9924 | AB12: 0.4701 | AC12: 0.5935 | AD12: 0.82 | AE12: 1 | AF12: 0.8659 | AG12: 52.35 | AH12: 0 | AI12: AVAILABLE — exact from 2026_Board_J-B_Run2.xlsx | AJ12: 10.93 | AK12: 10.58 | AL12: 9.46 | AM12: 51.448378 | AN12: 2 | AO12: 16 | AP12: 2025 Baxter fitted rating | AQ12: 36.013865 | AR12: 2 | AS12: -0.59430153 | AT12: 35.419563 | AU12: 3 | AW12: BLOCKED | AX12: No play-by-play/drive efficiency, scoring-opportunity, explosiveness, field-position, havoc, or special-teams results; official SP+ coefficients are unavailable. | AY12: 24.257522 | AZ12: 124.25752 | BA12: 2 | BB12: B | BE12: INITIALIZATION ONLY | BF12: 0.0082779388 | BG12: 80 | BH12: 12 | BI12: 12 | BJ12: 0 | BL12: PARTIAL — TOPOLOGY ONLY | BM12: =(F12-'Ensemble Parameters'!$B$20)/'Ensemble Parameters'!$C$20 -> 2.362539 | BN12: =(L12-'Ensemble Parameters'!$B$21)/'Ensemble Parameters'!$C$21 -> 2.2419173 | BO12: =(S12-'Ensemble Parameters'!$B$22)/'Ensemble Parameters'!$C$22 -> 2.2234823 | BP12: =(W12-'Ensemble Parameters'!$B$23)/'Ensemble Parameters'!$C$23 -> 2.218713 | BQ12: =AVERAGE(BO12:BP12) -> 2.2210977 | BR12: =(AQ12-'Ensemble Parameters'!$B$24)/'Ensemble Parameters'!$C$24 -> 2.3953259 | BS12: =BM12*'Ensemble Parameters'!$B$5+BN12*'Ensemble Parameters'!$B$6+BQ12*'Ensemble Parameters'!$B$8+BR12*'Ensemble Parameters'!$B$7 -> 2.30522 | BT12: ='Ensemble Parameters'!$B$11+'Ensemble Parameters'!$B$12*BS12 -> 123.0522 | BU12: ='Ensemble Parameters'!$B$13*BS12 -> 32.27308 | BV12: =RANK(BT12,$BT$5:$BT$125,0) -> 2 | BW12: =STDEV(BM12,BN12,BQ12,BR12) -> 0.086580097 | BX12: =IF(BW12<'Ensemble Parameters'!$B$14,"High",IF(BW12<'Ensemble Parameters'!$B$15,"Moderate","Low")) -> High | BY12: =IF(BX12="Low","REVIEW — MODEL DISAGREEMENT","") | BZ12: 4
A13: ACC | B13: NC State | C13: NCSU | D13: 59 | E13: NCSU | F13: 25.395594 | G13: 46 | H13: 3.9659822 | I13: 13.497648 | J13: 2025_POSTERIOR_CARRYOVER | K13: P0_REGRESSED_2025_POSTERIOR | L13: 0.14536912 | M13: 100.14537 | N13: 42 | O13: 0.63529524 | P13: 2.1647238 | Q13: Complete | R13: PASS | S13: 0.552959 | T13: 34 | U13: 0.554127 | V13: 31 | W13: 0.563665 | X13: 30 | Y13: 0.56388144 | Z13: 31 | AA13: 0.4449 | AB13: 0.601 | AC13: 0.4942 | AD13: 0.642 | AE13: 1 | AF13: 0.5661 | AG13: 21.46 | AH13: -3 | AI13: AVAILABLE — exact from 2026_Board_J-B_Run2.xlsx | AJ13: 6.71 | AK13: 6.73 | AL13: 7.43 | AM13: -6.9128144 | AN13: 57 | AO13: 13 | AP13: 2025 Baxter fitted rating | AQ13: -4.8389701 | AR13: 57 | AS13: 1.0200557 | AT13: -3.8189145 | AU13: 52 | AW13: BLOCKED | AX13: No play-by-play/drive efficiency, scoring-opportunity, explosiveness, field-position, havoc, or special-teams results; official SP+ coefficients are unavailable. | AY13: 0.61642367 | AZ13: 100.61642 | BA13: 39 | BB13: B | BE13: INITIALIZATION ONLY | BF13: 0.0082680138 | BG13: 90 | BH13: 12 | BI13: 12 | BJ13: 0 | BL13: PARTIAL — TOPOLOGY ONLY | BM13: =(F13-'Ensemble Parameters'!$B$20)/'Ensemble Parameters'!$C$20 -> 0.056470635 | BN13: =(L13-'Ensemble Parameters'!$B$21)/'Ensemble Parameters'!$C$21 -> 0.015237728 | BO13: =(S13-'Ensemble Parameters'!$B$22)/'Ensemble Parameters'!$C$22 -> 0.5232537 | BP13: =(W13-'Ensemble Parameters'!$B$23)/'Ensemble Parameters'!$C$23 -> 0.58838432 | BQ13: =AVERAGE(BO13:BP13) -> 0.55581901 | BR13: =(AQ13-'Ensemble Parameters'!$B$24)/'Ensemble Parameters'!$C$24 -> -0.3154035 | BS13: =BM13*'Ensemble Parameters'!$B$5+BN13*'Ensemble Parameters'!$B$6+BQ13*'Ensemble Parameters'!$B$8+BR13*'Ensemble Parameters'!$B$7 -> 0.078030968 | BT13: ='Ensemble Parameters'!$B$11+'Ensemble Parameters'!$B$12*BS13 -> 100.78031 | BU13: ='Ensemble Parameters'!$B$13*BS13 -> 1.0924335 | BV13: =RANK(BT13,$BT$5:$BT$125,0) -> 41 | BW13: =STDEV(BM13,BN13,BQ13,BR13) -> 0.35938834 | BX13: =IF(BW13<'Ensemble Parameters'!$B$14,"High",IF(BW13<'Ensemble Parameters'!$B$15,"Moderate","Low")) -> Moderate | BY13: =IF(BX13="Low","REVIEW — MODEL DISAGREEMENT","") | BZ13: 4
A14: ACC | B14: North Carolina | C14: UNC | D14: 60 | E14: UNC | F14: 25.68621 | G14: 42 | H14: 4.0284069 | I14: 13.600989 | J14: 2025_POSTERIOR_CARRYOVER | K14: P0_REGRESSED_2025_POSTERIOR | L14: -2.9939108 | M14: 97.006089 | N14: 64 | O14: 0.54992381 | P14: 0.79878095 | Q14: Complete | R14: PASS | S14: 0.471257 | T14: 54 | U14: 0.457368 | V14: 63 | W14: 0.48696 | X14: 59 | Y14: 0.47167465 | Z14: 63 | AA14: 0.368 | AB14: 0.4103 | AC14: 0.482 | AD14: 0.706 | AE14: 0.85 | AF14: 0.315 | AG14: 18.61 | AH14: 9 | AI14: AVAILABLE — exact from 2026_Board_J-B_Run2.xlsx | AJ14: 4.38 | AK14: 4.51 | AL14: 4.54 | AM14: -9.4910145 | AN14: 66 | AO14: 13 | AP14: 2025 Baxter fitted rating | AQ14: -6.6437102 | AR14: 68 | AS14: 0.12607156 | AT14: -6.5176386 | AU14: 70 | AW14: BLOCKED | AX14: No play-by-play/drive efficiency, scoring-opportunity, explosiveness, field-position, havoc, or special-teams results; official SP+ coefficients are unavailable. | AY14: -4.5316562 | AZ14: 95.468344 | BA14: 76 | BB14: B | BE14: INITIALIZATION ONLY | BF14: 0.0082747777 | BG14: 84 | BH14: 12 | BI14: 12 | BJ14: 0 | BL14: PARTIAL — TOPOLOGY ONLY | BM14: =(F14-'Ensemble Parameters'!$B$20)/'Ensemble Parameters'!$C$20 -> 0.12313649 | BN14: =(L14-'Ensemble Parameters'!$B$21)/'Ensemble Parameters'!$C$21 -> -0.31382454 | BO14: =(S14-'Ensemble Parameters'!$B$22)/'Ensemble Parameters'!$C$22 -> -0.04650644 | BP14: =(W14-'Ensemble Parameters'!$B$23)/'Ensemble Parameters'!$C$23 -> -0.012636315 | BQ14: =AVERAGE(BO14:BP14) -> -0.029571378 | BR14: =(AQ14-'Ensemble Parameters'!$B$24)/'Ensemble Parameters'!$C$24 -> -0.43515436 | BS14: =BM14*'Ensemble Parameters'!$B$5+BN14*'Ensemble Parameters'!$B$6+BQ14*'Ensemble Parameters'!$B$8+BR14*'Ensemble Parameters'!$B$7 -> -0.16385345 | BT14: ='Ensemble Parameters'!$B$11+'Ensemble Parameters'!$B$12*BS14 -> 98.361466 | BU14: ='Ensemble Parameters'!$B$13*BS14 -> -2.2939482 | BV14: =RANK(BT14,$BT$5:$BT$125,0) -> 50 | BW14: =STDEV(BM14,BN14,BQ14,BR14) -> 0.25592343 | BX14: =IF(BW14<'Ensemble Parameters'!$B$14,"High",IF(BW14<'Ensemble Parameters'!$B$15,"Moderate","Low")) -> High | BY14: =IF(BX14="Low","REVIEW — MODEL DISAGREEMENT","") | BZ14: 4
A15: ACC | B15: Pittsburgh | C15: PITT | D15: 61 | E15: PITT | F15: 26.988322 | G15: 36 | H15: 4.0282769 | I15: 14.903492 | J15: 2025_POSTERIOR_CARRYOVER | K15: P0_REGRESSED_2025_POSTERIOR | L15: 3.3608622 | M15: 103.36086 | N15: 31 | O15: 0.60902857 | P15: 1.7444571 | Q15: Complete | R15: PASS | S15: 0.564913 | T15: 29 | U15: 0.563658 | V15: 29 | W15: 0.56274 | X15: 33 | Y15: 0.56167867 | Z15: 29 | AA15: 0.507 | AB15: 0.6527 | AC15: 0.443 | AD15: 0.59 | AE15: 0.85 | AF15: 0.5508 | AG15: 10.84 | AH15: 0 | AI15: AVAILABLE — exact from 2026_Board_J-B_Run2.xlsx | AJ15: 6.76 | AK15: 6.55 | AL15: 6.88 | AM15: 3.2965067 | AN15: 34 | AO15: 13 | AP15: 2025 Baxter fitted rating | AQ15: 2.3075547 | AR15: 34 | AS15: 0.25804875 | AT15: 2.5656035 | AU15: 34 | AW15: BLOCKED | AX15: No play-by-play/drive efficiency, scoring-opportunity, explosiveness, field-position, havoc, or special-teams results; official SP+ coefficients are unavailable. | AY15: 3.7095168 | AZ15: 103.70952 | BA15: 34 | BB15: B | BE15: INITIALIZATION ONLY | BF15: 0.0082824315 | BG15: 68 | BH15: 12 | BI15: 12 | BJ15: 0 | BL15: PARTIAL — TOPOLOGY ONLY | BM15: =(F15-'Ensemble Parameters'!$B$20)/'Ensemble Parameters'!$C$20 -> 0.42183482 | BN15: =(L15-'Ensemble Parameters'!$B$21)/'Ensemble Parameters'!$C$21 -> 0.35228873 | BO15: =(S15-'Ensemble Parameters'!$B$22)/'Ensemble Parameters'!$C$22 -> 0.60661656 | BP15: =(W15-'Ensemble Parameters'!$B$23)/'Ensemble Parameters'!$C$23 -> 0.5811365 | BQ15: =AVERAGE(BO15:BP15) -> 0.59387653 | BR15: =(AQ15-'Ensemble Parameters'!$B$24)/'Ensemble Parameters'!$C$24 -> 0.15879359 | BS15: =BM15*'Ensemble Parameters'!$B$5+BN15*'Ensemble Parameters'!$B$6+BQ15*'Ensemble Parameters'!$B$8+BR15*'Ensemble Parameters'!$B$7 -> 0.38169842 | BT15: ='Ensemble Parameters'!$B$11+'Ensemble Parameters'!$B$12*BS15 -> 103.81698 | BU15: ='Ensemble Parameters'!$B$13*BS15 -> 5.3437778 | BV15: =RANK(BT15,$BT$5:$BT$125,0) -> 32 | BW15: =STDEV(BM15,BN15,BQ15,BR15) -> 0.17998331 | BX15: =IF(BW15<'Ensemble Parameters'!$B$14,"High",IF(BW15<'Ensemble Parameters'!$B$15,"Moderate","Low")) -> High | BY15: =IF(BX15="Low","REVIEW — MODEL DISAGREEMENT","") | BZ15: 4
A16: ACC | B16: SMU | C16: SMU | D16: 62 | E16: SMU | F16: 28.816608 | G16: 25 | H16: 4.174492 | I16: 16.293132 | J16: 2025_POSTERIOR_CARRYOVER | K16: P0_REGRESSED_2025_POSTERIOR | L16: 4.7899904 | M16: 104.78999 | N16: 30 | O16: 0.69050476 | P16: 3.0480762 | Q16: Complete | R16: PASS | S16: 0.622525 | T16: 23 | U16: 0.626309 | V16: 23 | W16: 0.62634 | X16: 21 | Y16: 0.62978534 | Z16: 23 | AA16: 0.5333 | AB16: 0.6728 | AC16: 0.5217 | AD16: 0.747 | AE16: 1 | AF16: 0.6651 | AG16: 28.66 | AH16: 0 | AI16: AVAILABLE — exact from 2026_Board_J-B_Run2.xlsx | AJ16: 8.16 | AK16: 8.06 | AL16: 8.38 | AM16: 3.7496202 | AN16: 33 | AO16: 13 | AP16: 2025 Baxter fitted rating | AQ16: 2.6247341 | AR16: 33 | AS16: 1.4458039 | AT16: 4.0705381 | AU16: 30 | AW16: BLOCKED | AX16: No play-by-play/drive efficiency, scoring-opportunity, explosiveness, field-position, havoc, or special-teams results; official SP+ coefficients are unavailable. | AY16: 6.0530449 | AZ16: 106.05304 | BA16: 29 | BB16: B | BE16: INITIALIZATION ONLY | BF16: 0.0082800712 | BG16: 77 | BH16: 12 | BI16: 12 | BJ16: 0 | BL16: PARTIAL — TOPOLOGY ONLY | BM16: =(F16-'Ensemble Parameters'!$B$20)/'Ensemble Parameters'!$C$20 -> 0.84123493 | BN16: =(L16-'Ensemble Parameters'!$B$21)/'Ensemble Parameters'!$C$21 -> 0.50209129 | BO16: =(S16-'Ensemble Parameters'!$B$22)/'Ensemble Parameters'!$C$22 -> 1.0083818 | BP16: =(W16-'Ensemble Parameters'!$B$23)/'Ensemble Parameters'!$C$23 -> 1.0794731 | BQ16: =AVERAGE(BO16:BP16) -> 1.0439275 | BR16: =(AQ16-'Ensemble Parameters'!$B$24)/'Ensemble Parameters'!$C$24 -> 0.17983956 | BS16: =BM16*'Ensemble Parameters'!$B$5+BN16*'Ensemble Parameters'!$B$6+BQ16*'Ensemble Parameters'!$B$8+BR16*'Ensemble Parameters'!$B$7 -> 0.64177331 | BT16: ='Ensemble Parameters'!$B$11+'Ensemble Parameters'!$B$12*BS16 -> 106.41773 | BU16: ='Ensemble Parameters'!$B$13*BS16 -> 8.9848263 | BV16: =RANK(BT16,$BT$5:$BT$125,0) -> 30 | BW16: =STDEV(BM16,BN16,BQ16,BR16) -> 0.38052891 | BX16: =IF(BW16<'Ensemble Parameters'!$B$14,"High",IF(BW16<'Ensemble Parameters'!$B$15,"Moderate","Low")) -> Moderate | BY16: =IF(BX16="Low","REVIEW — MODEL DISAGREEMENT","") | BZ16: 4
... A21: ACC | B21: Wake Forest | C21: WAKE | D21: 67 | E21: WAKE | F21: 25.699938 | G21: 41 | H21: 4.068908 | I21: 13.493214 | J21: 2025_POSTERIOR_CARRYOVER | K21: P0_REGRESSED_2025_POSTERIOR | L21: 2.2640295 | M21: 102.26403 | N21: 36 | O21: 0.56280952 | P21: 1.0049524 | Q21: Complete | R21: PASS | S21: 0.532707 | T21: 38 | U21: 0.521408 | V21: 39 | W21: 0.538825 | X21: 38 | Y21: 0.52698276 | Z21: 39 | AA21: 0.4932 | AB21: 0.5089 | AC21: 0.4573 | AD21: 0.501 | AE21: 1 | AF21: 0.4056 | AG21: 13.44 | AH21: 1 | AI21: AVAILABLE — exact from 2026_Board_J-B_Run2.xlsx | AJ21: 5.44 | AK21: 5.5 | AL21: 6.06 | AM21: 1.7358697 | AN21: 36 | AO21: 13 | AP21: 2025 Baxter fitted rating | AQ21: 1.2151088 | AR21: 36 | AS21: -0.14196246 | AT21: 1.0731463 | AU21: 37 | AW21: BLOCKED | AX21: No play-by-play/drive efficiency, scoring-opportunity, explosiveness, field-position, havoc, or special-teams results; official SP+ coefficients are unavailable. | AY21: 1.451084 | AZ21: 101.45108 | BA21: 37 | BB21: B | BE21: INITIALIZATION ONLY | BF21: 0.0082777281 | BG21: 81 | BH21: 12 | BI21: 12 | BJ21: 0 | BL21: PARTIAL — TOPOLOGY ONLY | BM21: =(F21-'Ensemble Parameters'!$B$20)/'Ensemble Parameters'!$C$20 -> 0.12628557 | BN21: =(L21-'Ensemble Parameters'!$B$21)/'Ensemble Parameters'!$C$21 -> 0.23731769 | BO21: =(S21-'Ensemble Parameters'!$B$22)/'Ensemble Parameters'!$C$22 -> 0.38202359 | BP21: =(W21-'Ensemble Parameters'!$B$23)/'Ensemble Parameters'!$C$23 -> 0.39375095 | BQ21: =AVERAGE(BO21:BP21) -> 0.38788727 | BR21: =(AQ21-'Ensemble Parameters'!$B$24)/'Ensemble Parameters'!$C$24 -> 0.086305953 | BS21: =BM21*'Ensemble Parameters'!$B$5+BN21*'Ensemble Parameters'!$B$6+BQ21*'Ensemble Parameters'!$B$8+BR21*'Ensemble Parameters'!$B$7 -> 0.20944912 | BT21: ='Ensemble Parameters'!$B$11+'Ensemble Parameters'!$B$12*BS21 -> 102.09449 | BU21: ='Ensemble Parameters'!$B$13*BS21 -> 2.9322877 | BV21: =RANK(BT21,$BT$5:$BT$125,0) -> 36 | BW21: =STDEV(BM21,BN21,BQ21,BR21) -> 0.13502746 | BX21: =IF(BW21<'Ensemble Parameters'!$B$14,"High",IF(BW21<'Ensemble Parameters'!$B$15,"Moderate","Low")) -> High | BY21: =IF(BX21="Low","REVIEW — MODEL DISAGREEMENT","") | BZ21: 4
A22: American | B22: Army | C22: ARMY | D22: 86 | E22: ARMY | F22: 27.909466 | G22: 32 | H22: 4.1065612 | I22: 15.589783 | J22: 2025_POSTERIOR_CARRYOVER | K22: P0_REGRESSED_2025_POSTERIOR | L22: 1.8856321 | M22: 101.88563 | N22: 37 | O22: 0.52084706 | P22: 0.33355294 | Q22: Complete | R22: PASS | S22: 0.533713 | T22: 36 | U22: 0.543694 | V22: 36 | W22: 0.51493333 | X22: 39 | Y22: 0.52658372 | Z22: 36 | AA22: 0.5474 | AB22: 0.5875 | AC22: 0.3174 | AE22: 0.75 | AF22: 0.646 | AG22: 0 | AH22: 0 | AI22: AVAILABLE — exact from 2026_Board_J-B_Run2.xlsx | AJ22: 8.45 | AK22: 7.96 | AL22: 7.88 | AM22: 3.9319077 | AN22: 32 | AO22: 13 | AP22: 2025 Baxter fitted rating | AQ22: 2.7523354 | AR22: 32 | AS22: -1.3519183 | AT22: 1.400417 | AU22: 35 | AW22: BLOCKED | AX22: No play-by-play/drive efficiency, scoring-opportunity, explosiveness, field-position, havoc, or special-teams results; official SP+ coefficients are unavailable. | AY22: 2.9958866 | AZ22: 102.99589 | BA22: 35 | BB22: B | BE22: INITIALIZATION ONLY | BF22: 0.0082923151 | BG22: 58 | BH22: 12 | BI22: 12 | BJ22: 0 | BL22: PARTIAL — TOPOLOGY ONLY | BM22: =(F22-'Ensemble Parameters'!$B$20)/'Ensemble Parameters'!$C$20 -> 0.63314089 | BN22: =(L22-'Ensemble Parameters'!$B$21)/'Ensemble Parameters'!$C$21 -> 0.19765372 | BO22: =(S22-'Ensemble Parameters'!$B$22)/'Ensemble Parameters'!$C$22 -> 0.38903907 | BP22: =(W22-'Ensemble Parameters'!$B$23)/'Ensemble Parameters'!$C$23 -> 0.20654823 | BQ22: =AVERAGE(BO22:BP22) -> 0.29779365 | BR22: =(AQ22-'Ensemble Parameters'!$B$24)/'Ensemble Parameters'!$C$24 -> 0.18830635 | BS22: =BM22*'Ensemble Parameters'!$B$5+BN22*'Ensemble Parameters'!$B$6+BQ22*'Ensemble Parameters'!$B$8+BR22*'Ensemble Parameters'!$B$7 -> 0.32922365 | BT22: ='Ensemble Parameters'!$B$11+'Ensemble Parameters'!$B$12*BS22 -> 103.29224 | BU22: ='Ensemble Parameters'!$B$13*BS22 -> 4.6091311 | BV22: =RANK(BT22,$BT$5:$BT$125,0) -> 33 | BW22: =STDEV(BM22,BN22,BQ22,BR22) -> 0.20858401 | BX22: =IF(BW22<'Ensemble Parameters'!$B$14,"High",IF(BW22<'Ensemble Parameters'!$B$15,"Moderate","Low")) -> High | BY22: =IF(BX22="Low","REVIEW — MODEL DISAGREEMENT","") | BZ22: 4
A23: American | B23: East Carolina | C23: ECU | D23: 87 | E23: ECU | F23: 27.642791 | G23: 34 | H23: 4.1235448 | I23: 15.272156 | J23: 2025_POSTERIOR_CARRYOVER | K23: P0_REGRESSED_2025_POSTERIOR | L23: 0.40465083 | M23: 100.40465 | N23: 40 | O23: 0.47072381 | P23: -0.46841905 | Q23: Complete | R23: PASS | S23: 0.482176 | T23: 45 | U23: 0.486142 | V23: 58 | W23: 0.48514 | X23: 47 | Y23: 0.48884312 | Z23: 58 | AA23: 0.4972 | AB23: 0.3736 | AC23: 0.4524 | AD23: 0.483 | AE23: 0.75 | AF23: 0.5268 | AG23: 12.52 | AH23: 13 | AI23: AVAILABLE — exact from 2026_Board_J-B_Run2.xlsx | AJ23: 6.64 | AK23: 6.62 | AL23: 6.58 | AM23: 0.26638485 | AN23: 37 | AO23: 13 | AP23: 2025 Baxter fitted rating | AQ23: 0.1864694 | AR23: 37 | AS23: -1.4568294 | AT23: -1.27036 | AU23: 43 | AW23: BLOCKED | AX23: No play-by-play/drive efficiency, scoring-opportunity, explosiveness, field-position, havoc, or special-teams results; official SP+ coefficients are unavailable. | AY23: 0.56130537 | AZ23: 100.56131 | BA23: 40 | BB23: B | BE23: INITIALIZATION ONLY | BF23: 0.0082917685 | BG23: 59 | BH23: 12 | BI23: 12 | BJ23: 0 | BL23: PARTIAL — TOPOLOGY ONLY | BM23: =(F23-'Ensemble Parameters'!$B$20)/'Ensemble Parameters'!$C$20 -> 0.57196679 | BN23: =(L23-'Ensemble Parameters'!$B$21)/'Ensemble Parameters'!$C$21 -> 0.04241588 | BO23: =(S23-'Ensemble Parameters'!$B$22)/'Ensemble Parameters'!$C$22 -> 0.029638709 | BP23: =(W23-'Ensemble Parameters'!$B$23)/'Ensemble Parameters'!$C$23 -> -0.026896892 | BQ23: =AVERAGE(BO23:BP23) -> 0.0013709082 | BR23: =(AQ23-'Ensemble Parameters'!$B$24)/'Ensemble Parameters'!$C$24 -> 0.018052107 | BS23: =BM23*'Ensemble Parameters'!$B$5+BN23*'Ensemble Parameters'!$B$6+BQ23*'Ensemble Parameters'!$B$8+BR23*'Ensemble Parameters'!$B$7 -> 0.15845142 | BT23: ='Ensemble Parameters'!$B$11+'Ensemble Parameters'!$B$12*BS23 -> 101.58451 | BU23: ='Ensemble Parameters'!$B$13*BS23 -> 2.2183199 | BV23: =RANK(BT23,$BT$5:$BT$125,0) -> 38 | BW23: =STDEV(BM23,BN23,BQ23,BR23) -> 0.27619164 | BX23: =IF(BW23<'Ensemble Parameters'!$B$14,"High",IF(BW23<'Ensemble Parameters'!$B$15,"Moderate","Low")) -> High | BY23: =IF(BX23="Low","REVIEW — MODEL DISAGREEMENT","") | BZ23: 4
A24: American | B24: Florida Atlantic | C24: FAU | D24: 88 | E24: FAU | F24: 21.003332 | G24: 105 | H24: 4.4136237 | I24: 7.7624614 | J24: 2025_POSTERIOR_CARRYOVER | K24: P0_REGRESSED_2025_POSTERIOR | L24: -4.9846135 | M24: 95.015387 | N24: 81 | O24: 0.58818095 | P24: 1.4108952 | Q24: Complete | R24: PASS | S24: 0.422999 | T24: 73 | U24: 0.418777 | V24: 71 | W24: 0.444065 | X24: 70 | Y24: 0.43797033 | Z24: 71 | AA24: 0.2062 | AB24: 0.6981 | AC24: 0.4435 | AD24: 0.464 | AE24: 0.75 | AF24: 0.3755 | AG24: 10.92 | AH24: -2 | AI24: AVAILABLE — exact from 2026_Board_J-B_Run2.xlsx | AJ24: 5.37 | AK24: 5.66 | AL24: 7.17 | AM24: -14.183874 | AN24: 86 | AO24: 12 | AP24: 2025 Baxter fitted rating | AQ24: -9.9287116 | AR24: 88 | AS24: 1.0420724 | AT24: -8.8866392 | AU24: 86 | AW24: BLOCKED | AX24: No play-by-play/drive efficiency, scoring-opportunity, explosiveness, field-position, havoc, or special-teams results; official SP+ coefficients are unavailable. | AY24: -6.0383589 | AZ24: 93.961641 | BA24: 82 | BB24: B | BE24: INITIALIZATION ONLY | BF24: 0.0082821104 | BG24: 70 | BH24: 12 | BI24: 12 | BJ24: 0 | BL24: PARTIAL — TOPOLOGY ONLY | BM24: =(F24-'Ensemble Parameters'!$B$20)/'Ensemble Parameters'!$C$20 -> -0.95109339 | BN24: =(L24-'Ensemble Parameters'!$B$21)/'Ensemble Parameters'!$C$21 -> -0.52249187 | BO24: =(S24-'Ensemble Parameters'!$B$22)/'Ensemble Parameters'!$C$22 -> -0.38304024 | BP24: =(W24-'Ensemble Parameters'!$B$23)/'Ensemble Parameters'!$C$23 -> -0.34873931 | BQ24: =AVERAGE(BO24:BP24) -> -0.36588978 | BR24: =(AQ24-'Ensemble Parameters'!$B$24)/'Ensemble Parameters'!$C$24 -> -0.65312577 | BS24: =BM24*'Ensemble Parameters'!$B$5+BN24*'Ensemble Parameters'!$B$6+BQ24*'Ensemble Parameters'!$B$8+BR24*'Ensemble Parameters'!$B$7 -> -0.6231502 | BT24: ='Ensemble Parameters'!$B$11+'Ensemble Parameters'!$B$12*BS24 -> 93.768498 | BU24: ='Ensemble Parameters'!$B$13*BS24 -> -8.7241028 | BV24: =RANK(BT24,$BT$5:$BT$125,0) -> 82 | BW24: =STDEV(BM24,BN24,BQ24,BR24) -> 0.24816681 | BX24: =IF(BW24<'Ensemble Parameters'!$B$14,"High",IF(BW24<'Ensemble Parameters'!$B$15,"Moderate","Low")) -> High | BY24: =IF(BX24="Low","REVIEW — MODEL DISAGREEMENT","") | BZ24: 4
A25: American | B25: Louisiana Tech | C25: LT | D25: 89 | E25: LT | F25: 20.447448 | G25: 112 | H25: 4.1212429 | I25: 8.0837198 | J25: 2025_POSTERIOR_CARRYOVER | K25: P0_REGRESSED_2025_POSTERIOR | L25: -8.2973205 | M25: 91.702679 | N25: 97 | O25: 0.49294286 | P25: -0.11291429 | Q25: Complete | R25: PASS | S25: 0.342613 | T25: 100 | U25: 0.353697 | V25: 97 | W25: 0.37201 | X25: 97 | Y25: 0.38048023 | Z25: 97 | AA25: 0.1453 | AB25: 0.5032 | AC25: 0.4361 | AD25: 0.3649 | AE25: 0.75 | AF25: 0.4673 | AG25: 9.68 | AH25: -3 | AI25: AVAILABLE — exact from 2026_Board_J-B_Run2.xlsx | AJ25: 5.68 | AK25: 5.94 | AL25: 7.03 | AM25: -17.169535 | AN25: 90 | AO25: 12 | AP25: 2025 Baxter fitted rating | AQ25: -12.018674 | AR25: 92 | AS25: 0.067142934 | AT25: -11.951531 | AU25: 94 | AW25: BLOCKED | AX25: No play-by-play/drive efficiency, scoring-opportunity, explosiveness, field-position, havoc, or special-teams results; official SP+ coefficients are unavailable. | AY25: -8.616666 | AZ25: 91.383334 | BA25: 96 | BB25: B | BE25: INITIALIZATION ONLY | BF25: 0.0071363557 | BG25: 120 | BH25: 12 | BI25: 10 | BJ25: 2 | BL25: PARTIAL — TOPOLOGY ONLY | BM25: =(F25-'Ensemble Parameters'!$B$20)/'Ensemble Parameters'!$C$20 -> -1.0786105 | BN25: =(L25-'Ensemble Parameters'!$B$21)/'Ensemble Parameters'!$C$21 -> -0.86973293 | BO25: =(S25-'Ensemble Parameters'!$B$22)/'Ensemble Parameters'!$C$22 -> -0.94362307 | BP25: =(W25-'Ensemble Parameters'!$B$23)/'Ensemble Parameters'!$C$23 -> -0.91332495 | BQ25: =AVERAGE(BO25:BP25) -> -0.92847401 | BR25: =(AQ25-'Ensemble Parameters'!$B$24)/'Ensemble Parameters'!$C$24 -> -0.79180216 | BS25: =BM25*'Ensemble Parameters'!$B$5+BN25*'Ensemble Parameters'!$B$6+BQ25*'Ensemble Parameters'!$B$8+BR25*'Ensemble Parameters'!$B$7 -> -0.91715491 | BT25: ='Ensemble Parameters'!$B$11+'Ensemble Parameters'!$B$12*BS25 -> 90.828451 | BU25: ='Ensemble Parameters'!$B$13*BS25 -> -12.840169 | BV25: =RANK(BT25,$BT$5:$BT$125,0) -> 107 | BW25: =STDEV(BM25,BN25,BQ25,BR25) -> 0.12132353 | BX25: =IF(BW25<'Ensemble Parameters'!$B$14,"High",IF(BW25<'Ensemble Parameters'!$B$15,"Moderate","Low")) -> High | BY25: =IF(BX25="Low","REVIEW — MODEL DISAGREEMENT","") | BZ25: 4
A26: American | B26: Memphis | C26: MEM | D26: 90 | E26: MEM | F26: 25.333987 | G26: 47 | H26: 4.1484511 | I26: 12.888634 | J26: 2025_POSTERIOR_CARRYOVER | K26: P0_REGRESSED_2025_POSTERIOR | L26: -5.0067626 | M26: 94.993237 | N26: 82 | O26: 0.43202857 | P26: -1.0875429 | Q26: Complete | R26: PASS | S26: 0.404736 | T26: 69 | U26: 0.423791 | V26: 78 | W26: 0.411165 | X26: 75 | Y26: 0.42964813 | Z26: 78 | AA26: 0.3689 | AB26: 0.362 | AC26: 0.4586 | AD26: 0.575 | AE26: 0.375 | AF26: 0.6191 | AG26: 13.7 | AH26: 9 | AI26: AVAILABLE — exact from 2026_Board_J-B_Run2.xlsx | AJ26: 5.83 | AK26: 5.61 | AL26: 4.09 | AM26: -9.15557 | AN26: 64 | AO26: 13 | AP26: 2025 Baxter fitted rating | AQ26: -6.408899 | AR26: 66 | AS26: -1.6737349 | AT26: -8.0826339 | AU26: 81 | AW26: BLOCKED | AX26: No play-by-play/drive efficiency, scoring-opportunity, explosiveness, field-position, havoc, or special-teams results; official SP+ coefficients are unavailable. | AY26: -4.1117081 | AZ26: 95.888292 | BA26: 69 | BB26: B | BE26: INITIALIZATION ONLY | BF26: 0.0083691467 | BG26: 6 | BH26: 12 | BI26: 12 | BJ26: 0 | BL26: PARTIAL — TOPOLOGY ONLY | BM26: =(F26-'Ensemble Parameters'!$B$20)/'Ensemble Parameters'!$C$20 -> 0.042338142 | BN26: =(L26-'Ensemble Parameters'!$B$21)/'Ensemble Parameters'!$C$21 -> -0.52481356 | BO26: =(S26-'Ensemble Parameters'!$B$22)/'Ensemble Parameters'!$C$22 -> -0.51039978 | BP26: =(W26-'Ensemble Parameters'!$B$23)/'Ensemble Parameters'!$C$23 -> -0.60652666 | BQ26: =AVERAGE(BO26:BP26) -> -0.55846322 | BR26: =(AQ26-'Ensemble Parameters'!$B$24)/'Ensemble Parameters'!$C$24 -> -0.41957381 | BS26: =BM26*'Ensemble Parameters'!$B$5+BN26*'Ensemble Parameters'!$B$6+BQ26*'Ensemble Parameters'!$B$8+BR26*'Ensemble Parameters'!$B$7 -> -0.36512811 | BT26: ='Ensemble Parameters'!$B$11+'Ensemble Parameters'!$B$12*BS26 -> 96.348719 | BU26: ='Ensemble Parameters'!$B$13*BS26 -> -5.1117936 | BV26: =RANK(BT26,$BT$5:$BT$125,0) -> 67 | BW26: =STDEV(BM26,BN26,BQ26,BR26) -> 0.27801139 | BX26: =IF(BW26<'Ensemble Parameters'!$B$14,"High",IF(BW26<'Ensemble Parameters'!$B$15,"Moderate","Low")) -> High | BY26: =IF(BX26="Low","REVIEW — MODEL DISAGREEMENT","") | BZ26: 4
A27: American | B27: Navy | C27: NAVY | D27: 91 | E27: NAVY | F27: 33.40456 | G27: 8 | H27: 4.3104771 | I27: 20.473129 | J27: 2025_POSTERIOR_CARRYOVER | K27: P0_REGRESSED_2025_POSTERIOR | L27: 3.2668995 | M27: 103.2669 | N27: 32 | O27: 0.4496 | P27: -0.8064 | Q27: Complete | R27: PASS | S27: 0.559895 | T27: 30 | U27: 0.560713 | V27: 35 | W27: 0.53172778 | X27: 36 | Y27: 0.53504976 | Z27: 35 | AA27: 0.6771 | AB27: 0.4361 | AC27: 0.3174 | AE27: 0.75 | AF27: 0.5691 | AG27: 0 | AH27: 5 | AI27: AVAILABLE — exact from 2026_Board_J-B_Run2.xlsx | AJ27: 8.29 | AK27: 7.63 | AL27: 6.91 | AM27: 7.5185339 | AN27: 30 | AO27: 14 | AP27: 2025 Baxter fitted rating | AQ27: 5.2629737 | AR27: 30 | AS27: -2.5014 | AT27: 2.7615737 | AU27: 33 | AW27: BLOCKED | AX27: No play-by-play/drive efficiency, scoring-opportunity, explosiveness, field-position, havoc, or special-teams results; official SP+ coefficients are unavailable. | AY27: 3.7619541 | AZ27: 103.76195 | BA27: 32 | BB27: B | BE27: INITIALIZATION ONLY | BF27: 0.0082975916 | BG27: 49 | BH27: 12 | BI27: 12 | BJ27: 0 | BL27: PARTIAL — TOPOLOGY ONLY | BM27: =(F27-'Ensemble Parameters'!$B$20)/'Ensemble Parameters'!$C$20 -> 1.8936892 | BN27: =(L27-'Ensemble Parameters'!$B$21)/'Ensemble Parameters'!$C$21 -> 0.34243948 | BO27: =(S27-'Ensemble Parameters'!$B$22)/'Ensemble Parameters'!$C$22 -> 0.57162285 | BP27: =(W27-'Ensemble Parameters'!$B$23)/'Ensemble Parameters'!$C$23 -> 0.3381408 | BQ27: =AVERAGE(BO27:BP27) -> 0.45488182 | BR27: =(AQ27-'Ensemble Parameters'!$B$24)/'Ensemble Parameters'!$C$24 -> 0.35489605 | BS27: =BM27*'Ensemble Parameters'!$B$5+BN27*'Ensemble Parameters'!$B$6+BQ27*'Ensemble Parameters'!$B$8+BR27*'Ensemble Parameters'!$B$7 -> 0.76147664 | BT27: ='Ensemble Parameters'!$B$11+'Ensemble Parameters'!$B$12*BS27 -> 107.61477 | BU27: ='Ensemble Parameters'!$B$13*BS27 -> 10.660673 | BV27: =RANK(BT27,$BT$5:$BT$125,0) -> 28 | BW27: =STDEV(BM27,BN27,BQ27,BR27) -> 0.75648432 | BX27: =IF(BW27<'Ensemble Parameters'!$B$14,"High",IF(BW27<'Ensemble Parameters'!$B$15,"Moderate","Low")) -> Low | BY27: =IF(BX27="Low","REVIEW — MODEL DISAGREEMENT","") -> REVIEW — MODEL DISAGREEMENT | BZ27: 4
A28: American | B28: New Mexico State | C28: NMSU | D28: 92 | E28: NMSU | F28: 23.97717 | G28: 58 | H28: 4.0467932 | I28: 11.836791 | J28: 2025_POSTERIOR_CARRYOVER | K28: P0_REGRESSED_2025_POSTERIOR | L28: -8.2944689 | M28: 91.705531 | N28: 96 | O28: 0.4760381 | P28: -0.38339048 | Q28: Complete | R28: PASS | S28: 0.36194 | T28: 97 | U28: 0.355607 | V28: 100 | W28: 0.3865 | X28: 102 | Y28: 0.37798443 | Z28: 100 | AA28: 0.2122 | AB28: 0.4963 | AC28: 0.4356 | AD28: 0.2907 | AE28: 0.75 | AF28: 0.2907 | AG28: 9.59 | AH28: 3 | AI28: AVAILABLE — exact from 2026_Board_J-B_Run2.xlsx | AJ28: 5.09 | AK28: 5.3 | AL28: 6.32 | AM28: -17.15216 | AN28: 89 | AO28: 13 | AP28: 2025 Baxter fitted rating | AQ28: -12.006512 | AR28: 91 | AS28: -0.38821689 | AT28: -12.394729 | AU28: 97 | AW28: BLOCKED | AX28: No play-by-play/drive efficiency, scoring-opportunity, explosiveness, field-position, havoc, or special-teams results; official SP+ coefficients are unavailable. | AY28: -10.026614 | AZ28: 89.973386 | BA28: 107 | BB28: B | BE28: INITIALIZATION ONLY | BF28: 0.0083176671 | BG28: 31 | BH28: 12 | BI28: 12 | BJ28: 0 | BL28: PARTIAL — TOPOLOGY ONLY | BM28: =(F28-'Ensemble Parameters'!$B$20)/'Ensemble Parameters'!$C$20 -> -0.26890912 | BN28: =(L28-'Ensemble Parameters'!$B$21)/'Ensemble Parameters'!$C$21 -> -0.86943402 | BO28: =(S28-'Ensemble Parameters'!$B$22)/'Ensemble Parameters'!$C$22 -> -0.80884358 | BP28: =(W28-'Ensemble Parameters'!$B$23)/'Ensemble Parameters'!$C$23 -> -0.79978882 | BQ28: =AVERAGE(BO28:BP28) -> -0.8043162 | BR28: =(AQ28-'Ensemble Parameters'!$B$24)/'Ensemble Parameters'!$C$24 -> -0.79099514 | BS28: =BM28*'Ensemble Parameters'!$B$5+BN28*'Ensemble Parameters'!$B$6+BQ28*'Ensemble Parameters'!$B$8+BR28*'Ensemble Parameters'!$B$7 -> -0.68341362 | BT28: ='Ensemble Parameters'!$B$11+'Ensemble Parameters'!$B$12*BS28 -> 93.165864 | BU28: ='Ensemble Parameters'!$B$13*BS28 -> -9.5677907 | BV28: =RANK(BT28,$BT$5:$BT$125,0) -> 87 | BW28: =STDEV(BM28,BN28,BQ28,BR28) -> 0.27845334 | BX28: =IF(BW28<'Ensemble Parameters'!$B$14,"High",IF(BW28<'Ensemble Parameters'!$B$15,"Moderate","Low")) -> High | BY28: =IF(BX28="Low","REVIEW — MODEL DISAGREEMENT","") | BZ28: 4
A29: American | B29: North Texas | C29: UNT | D29: 93 | E29: UNT | F29: 27.924817 | G29: 31 | H29: 4.0323245 | I29: 15.827844 | J29: 2025_POSTERIOR_CARRYOVER | K29: P0_REGRESSED_2025_POSTERIOR | L29: -2.7326549 | M29: 97.267345 | N29: 59 | O29: 0.36920952 | P29: -2.0926476 | Q29: Complete | R29: PASS | S29: 0.42906 | T29: 66 | U29: 0.433553 | V29: 74 | W29: 0.42629 | X29: 74 | Y29: 0.43102867 | Z29: 74 | AA29: 0.5076 | AB29: 0.2884 | AC29: 0.4542 | AD29: 0.399 | AE29: 0.375 | AF29: 0.4796 | AG29: 12.86 | AH29: 8 | AI29: AVAILABLE — exact from 2026_Board_J-B_Run2.xlsx | AJ29: 5.73 | AK29: 5.47 | AL29: 4.04 | AM29: -2.1012885 | AN29: 44 | AO29: 14 | AP29: 2025 Baxter fitted rating | AQ29: -1.4709019 | AR29: 44 | AS29: -2.9698938 | AT29: -4.4407958 | AU29: 54 | AW29: BLOCKED | AX29: No play-by-play/drive efficiency, scoring-opportunity, explosiveness, field-position, havoc, or special-teams results; official SP+ coefficients are unavailable. | AY29: -2.9536004 | AZ29: 97.0464 | BA29: 62 | BB29: B | BE29: INITIALIZATION ONLY | BF29: 0.0083573996 | BG29: 13 | BH29: 12 | BI29: 12 | BJ29: 0 | BL29: PARTIAL — TOPOLOGY ONLY | BM29: =(F29-'Ensemble Parameters'!$B$20)/'Ensemble Parameters'!$C$20 -> 0.63666233 | BN29: =(L29-'Ensemble Parameters'!$B$21)/'Ensemble Parameters'!$C$21 -> -0.28643945 | BO29: =(S29-'Ensemble Parameters'!$B$22)/'Ensemble Parameters'!$C$22 -> -0.34077302 | BP29: =(W29-'Ensemble Parameters'!$B$23)/'Ensemble Parameters'!$C$23 -> -0.488015 | BQ29: =AVERAGE(BO29:BP29) -> -0.41439401 | BR29: =(AQ29-'Ensemble Parameters'!$B$24)/'Ensemble Parameters'!$C$24 -> -0.091920317 | BS29: =BM29*'Ensemble Parameters'!$B$5+BN29*'Ensemble Parameters'!$B$6+BQ29*'Ensemble Parameters'!$B$8+BR29*'Ensemble Parameters'!$B$7 -> -0.039022862 | BT29: ='Ensemble Parameters'!$B$11+'Ensemble Parameters'!$B$12*BS29 -> 99.609771 | BU29: ='Ensemble Parameters'!$B$13*BS29 -> -0.54632007 | BV29: =RANK(BT29,$BT$5:$BT$125,0) -> 46 | BW29: =STDEV(BM29,BN29,BQ29,BR29) -> 0.4695626 | BX29: =IF(BW29<'Ensemble Parameters'!$B$14,"High",IF(BW29<'Ensemble Parameters'!$B$15,"Moderate","Low")) -> Moderate | BY29: =IF(BX29="Low","REVIEW — MODEL DISAGREEMENT","") | BZ29: 4
A30: American | B30: Rice | C30: RICE | D30: 94 | E30: RICE | F30: 21.885029 | G30: 90 | H30: 4.1036922 | I30: 9.5739526 | J30: 2025_POSTERIOR_CARRYOVER | K30: P0_REGRESSED_2025_POSTERIOR | L30: -10.121894 | M30: 89.878106 | N30: 112 | O30: 0.46520952 | P30: -0.55664762 | Q30: Complete | R30: PASS | S30: 0.323145 | T30: 110 | U30: 0.322883 | V30: 112 | W30: 0.35404 | X30: 106 | Y30: 0.351032 | Z30: 112 | AA30: 0.1367 | AB30: 0.3918 | AC30: 0.4321 | AD30: 0.4481 | AE30: 0.75 | AF30: 0.3202 | AG30: 9.03 | AH30: 2 | AI30: AVAILABLE — exact from 2026_Board_J-B_Run2.xlsx | AJ30: 4.11 | AK30: 4.36 | AL30: 4.86 | AM30: -20.810896 | AN30: 111 | AO30: 12 | AP30: 2025 Baxter fitted rating | AQ30: -14.567627 | AR30: 113 | AS30: -0.25452045 | AT30: -14.822148 | AU30: 111 | AW30: BLOCKED | AX30: No play-by-play/drive efficiency, scoring-opportunity, explosiveness, field-position, havoc, or special-teams results; official SP+ coefficients are unavailable. | AY30: -11.618039 | AZ30: 88.381961 | BA30: 114 | BB30: B | BE30: INITIALIZATION ONLY | BF30: 0.0083266988 | BG30: 23 | BH30: 12 | BI30: 12 | BJ30: 0 | BL30: PARTIAL — TOPOLOGY ONLY | BM30: =(F30-'Ensemble Parameters'!$B$20)/'Ensemble Parameters'!$C$20 -> -0.74883633 | BN30: =(L30-'Ensemble Parameters'!$B$21)/'Ensemble Parameters'!$C$21 -> -1.0609864 | BO30: =(S30-'Ensemble Parameters'!$B$22)/'Ensemble Parameters'!$C$22 -> -1.0793858 | BP30: =(W30-'Ensemble Parameters'!$B$23)/'Ensemble Parameters'!$C$23 -> -1.0541286 | BQ30: =AVERAGE(BO30:BP30) -> -1.0667572 | BR30: =(AQ30-'Ensemble Parameters'!$B$24)/'Ensemble Parameters'!$C$24 -> -0.96093417 | BS30: =BM30*'Ensemble Parameters'!$B$5+BN30*'Ensemble Parameters'!$B$6+BQ30*'Ensemble Parameters'!$B$8+BR30*'Ensemble Parameters'!$B$7 -> -0.95937853 | BT30: ='Ensemble Parameters'!$B$11+'Ensemble Parameters'!$B$12*BS30 -> 90.406215 | BU30: ='Ensemble Parameters'!$B$13*BS30 -> -13.431299 | BV30: =RANK(BT30,$BT$5:$BT$125,0) -> 109 | BW30: =STDEV(BM30,BN30,BQ30,BR30) -> 0.14853146 | BX30: =IF(BW30<'Ensemble Parameters'!$B$14,"High",IF(BW30<'Ensemble Parameters'!$B$15,"Moderate","Low")) -> High | BY30: =IF(BX30="Low","REVIEW — MODEL DISAGREEMENT","") | BZ30: 4
A31: American | B31: South Florida | C31: USF | D31: 95 | E31: USF | F31: 21.622357 | G31: 98 | H31: 4.2606698 | I31: 8.8403477 | J31: 2025_POSTERIOR_CARRYOVER | K31: P0_REGRESSED_2025_POSTERIOR | L31: -3.7927018 | M31: 96.207298 | N31: 70 | O31: 0.44861905 | P31: -0.82209524 | Q31: Complete | R31: PASS | S31: 0.383969 | T31: 76 | U31: 0.414807 | V31: 83 | W31: 0.396465 | X31: 76 | Y31: 0.42619259 | Z31: 83 | AA31: 0.2991 | AB31: 0.4029 | AC31: 0.4688 | AD31: 0.565 | AE31: 0.375 | AF31: 0.7309 | AG31: 15.75 | AH31: 7 | AI31: AVAILABLE — exact from 2026_Board_J-B_Run2.xlsx | AJ31: 6.17 | AK31: 6.14 | AL31: 5.05 | AM31: -6.6379906 | AN31: 56 | AO31: 12 | AP31: 2025 Baxter fitted rating | AQ31: -4.6465934 | AR31: 56 | AS31: -1.1887667 | AT31: -5.8353601 | AU31: 65 | AW31: BLOCKED | AX31: No play-by-play/drive efficiency, scoring-opportunity, explosiveness, field-position, havoc, or special-teams results; official SP+ coefficients are unavailable. | AY31: -2.0032472 | AZ31: 97.996753 | BA31: 52 | BB31: B | BE31: INITIALIZATION ONLY | BF31: 0.0082882327 | BG31: 64 | BH31: 12 | BI31: 12 | BJ31: 0 | BL31: PARTIAL — TOPOLOGY ONLY | BM31: =(F31-'Ensemble Parameters'!$B$20)/'Ensemble Parameters'!$C$20 -> -0.80909207 | BN31: =(L31-'Ensemble Parameters'!$B$21)/'Ensemble Parameters'!$C$21 -> -0.39755456 | BO31: =(S31-'Ensemble Parameters'!$B$22)/'Ensemble Parameters'!$C$22 -> -0.65522132 | BP31: =(W31-'Ensemble Parameters'!$B$23)/'Ensemble Parameters'!$C$23 -> -0.72170825 | BQ31: =AVERAGE(BO31:BP31) -> -0.68846478 | BR31: =(AQ31-'Ensemble Parameters'!$B$24)/'Ensemble Parameters'!$C$24 -> -0.30263863 | BS31: =BM31*'Ensemble Parameters'!$B$5+BN31*'Ensemble Parameters'!$B$6+BQ31*'Ensemble Parameters'!$B$8+BR31*'Ensemble Parameters'!$B$7 -> -0.54943751 | BT31: ='Ensemble Parameters'!$B$11+'Ensemble Parameters'!$B$12*BS31 -> 94.505625 | BU31: ='Ensemble Parameters'!$B$13*BS31 -> -7.6921251 | BV31: =RANK(BT31,$BT$5:$BT$125,0) -> 76 | BW31: =STDEV(BM31,BN31,BQ31,BR31) -> 0.2385562 | BX31: =IF(BW31<'Ensemble Parameters'!$B$14,"High",IF(BW31<'Ensemble Parameters'!$B$15,"Moderate","Low")) -> High | BY31: =IF(BX31="Low","REVIEW — MODEL DISAGREEMENT","") | BZ31: 4
A32: American | B32: Southern Miss | C32: USM | D32: 96 | E32: USM | F32: 22.331904 | G32: 83 | H32: 4.2321504 | I32: 9.6354531 | J32: 2025_POSTERIOR_CARRYOVER | K32: P0_REGRESSED_2025_POSTERIOR | L32: -8.5082792 | M32: 91.491721 | N32: 99 | O32: 0.36362857 | P32: -2.1819429 | Q32: Complete | R32: PASS | S32: 0.29084 | T32: 116 | U32: 0.296365 | V32: 119 | W32: 0.313035 | X32: 118 | Y32: 0.31658745 | Z32: 119 | AA32: 0.1953 | AB32: 0.2514 | AC32: 0.444 | AD32: 0.459 | AE32: 0.375 | AF32: 0.353 | AG32: 11.01 | AH32: 3 | AI32: AVAILABLE — exact from 2026_Board_J-B_Run2.xlsx | AJ32: 3.89 | AK32: 4.06 | AL32: 3.54 | AM32: -13.36486 | AN32: 85 | AO32: 12 | AP32: 2025 Baxter fitted rating | AQ32: -9.3554017 | AR32: 87 | AS32: -1.9208665 | AT32: -11.276268 | AU32: 91 | AW32: BLOCKED | AX32: No play-by-play/drive efficiency, scoring-opportunity, explosiveness, field-position, havoc, or special-teams results; official SP+ coefficients are unavailable. | AY32: -9.7420246 | AZ32: 90.257975 | BA32: 103 | BB32: B | BE32: INITIALIZATION ONLY | BF32: 0.0083021875 | BG32: 41 | BH32: 12 | BI32: 12 | BJ32: 0 | BL32: PARTIAL — TOPOLOGY ONLY | BM32: =(F32-'Ensemble Parameters'!$B$20)/'Ensemble Parameters'!$C$20 -> -0.64632529 | BN32: =(L32-'Ensemble Parameters'!$B$21)/'Ensemble Parameters'!$C$21 -> -0.89184582 | BO32: =(S32-'Ensemble Parameters'!$B$22)/'Ensemble Parameters'!$C$22 -> -1.3046692 | BP32: =(W32-'Ensemble Parameters'!$B$23)/'Ensemble Parameters'!$C$23 -> -1.3754225 | BQ32: =AVERAGE(BO32:BP32) -> -1.3400459 | BR32: =(AQ32-'Ensemble Parameters'!$B$24)/'Ensemble Parameters'!$C$24 -> -0.61508464 | BS32: =BM32*'Ensemble Parameters'!$B$5+BN32*'Ensemble Parameters'!$B$6+BQ32*'Ensemble Parameters'!$B$8+BR32*'Ensemble Parameters'!$B$7 -> -0.8733254 | BT32: ='Ensemble Parameters'!$B$11+'Ensemble Parameters'!$B$12*BS32 -> 91.266746 | BU32: ='Ensemble Parameters'!$B$13*BS32 -> -12.226556 | BV32: =RANK(BT32,$BT$5:$BT$125,0) -> 105 | BW32: =STDEV(BM32,BN32,BQ32,BR32) -> 0.33485734 | BX32: =IF(BW32<'Ensemble Parameters'!$B$14,"High",IF(BW32<'Ensemble Parameters'!$B$15,"Moderate","Low")) -> Moderate | BY32: =IF(BX32="Low","REVIEW — MODEL DISAGREEMENT","") | BZ32: 4
A33: American | B33: Temple | C33: TEM | D33: 97 | E33: TEM | F33: 25.586865 | G33: 44 | H33: 4.1497056 | I33: 13.137748 | J33: 2025_POSTERIOR_CARRYOVER | K33: P0_REGRESSED_2025_POSTERIOR | L33: -2.8755371 | M33: 97.124463 | N33: 62 | O33: 0.5236 | P33: 0.3776 | Q33: Complete | R33: PASS | S33: 0.451937 | T33: 59 | U33: 0.452156 | V33: 69 | W33: 0.462985 | X33: 62 | Y33: 0.46222189 | Z33: 69 | AA33: 0.3579 | AB33: 0.4914 | AC33: 0.4408 | AD33: 0.5424 | AE33: 0.75 | AF33: 0.4544 | AG33: 10.45 | AH33: 10 | AI33: AVAILABLE — exact from 2026_Board_J-B_Run2.xlsx | AJ33: 6.71 | AK33: 6.8 | AL33: 7.36 | AM33: -7.9361132 | AN33: 59 | AO33: 13 | AP33: 2025 Baxter fitted rating | AQ33: -5.5552792 | AR33: 61 | AS33: -0.31945639 | AT33: -5.8747356 | AU33: 66 | AW33: BLOCKED | AX33: No play-by-play/drive efficiency, scoring-opportunity, explosiveness, field-position, havoc, or special-teams results; official SP+ coefficients are unavailable. | AY33: -3.2980826 | AZ33: 96.701917 | BA33: 64 | BB33: B | BE33: INITIALIZATION ONLY | BF33: 0.0083211809 | BG33: 28 | BH33: 12 | BI33: 12 | BJ33: 0 | BL33: PARTIAL — TOPOLOGY ONLY | BM33: =(F33-'Ensemble Parameters'!$B$20)/'Ensemble Parameters'!$C$20 -> 0.10034709 | BN33: =(L33-'Ensemble Parameters'!$B$21)/'Ensemble Parameters'!$C$21 -> -0.3014165 | BO33: =(S33-'Ensemble Parameters'!$B$22)/'Ensemble Parameters'!$C$22 -> -0.18123712 | BP33: =(W33-'Ensemble Parameters'!$B$23)/'Ensemble Parameters'!$C$23 -> -0.20049199 | BQ33: =AVERAGE(BO33:BP33) -> -0.19086456 | BR33: =(AQ33-'Ensemble Parameters'!$B$24)/'Ensemble Parameters'!$C$24 -> -0.36293313 | BS33: =BM33*'Ensemble Parameters'!$B$5+BN33*'Ensemble Parameters'!$B$6+BQ33*'Ensemble Parameters'!$B$8+BR33*'Ensemble Parameters'!$B$7 -> -0.18871677 | BT33: ='Ensemble Parameters'!$B$11+'Ensemble Parameters'!$B$12*BS33 -> 98.112832 | BU33: ='Ensemble Parameters'!$B$13*BS33 -> -2.6420348 | BV33: =RANK(BT33,$BT$5:$BT$125,0) -> 52 | BW33: =STDEV(BM33,BN33,BQ33,BR33) -> 0.20543863 | BX33: =IF(BW33<'Ensemble Parameters'!$B$14,"High",IF(BW33<'Ensemble Parameters'!$B$15,"Moderate","Low")) -> High | BY33: =IF(BX33="Low","REVIEW — MODEL DISAGREEMENT","") | BZ33: 4
A34: American | B34: Tulane | C34: TLN | D34: 98 | E34: TLN | F34: 31.447406 | G34: 17 | H34: 4.3180268 | I34: 18.493326 | J34: 2025_POSTERIOR_CARRYOVER | K34: P0_REGRESSED_2025_POSTERIOR | L34: 5.7071294 | M34: 105.70713 | N34: 28 | O34: 0.43749524 | P34: -1.0000762 | Q34: Complete | R34: PASS | S34: 0.548755 | T34: 32 | U34: 0.558163 | V34: 38 | W34: 0.52672 | X34: 35 | Y34: 0.53808713 | Z34: 38 | AA34: 0.6948 | AB34: 0.4092 | AC34: 0.4448 | AD34: 0.53 | AE34: 0.375 | AF34: 0.6546 | AG34: 11.14 | AH34: 6 | AI34: AVAILABLE — exact from 2026_Board_J-B_Run2.xlsx | AJ34: 8.86 | AK34: 8.16 | AL34: 5.8 | AM34: 14.13199 | AN34: 28 | AO34: 14 | AP34: 2025 Baxter fitted rating | AQ34: 9.8923927 | AR34: 28 | AS34: -2.8305717 | AT34: 7.061821 | AU34: 28 | AW34: BLOCKED | AX34: No play-by-play/drive efficiency, scoring-opportunity, explosiveness, field-position, havoc, or special-teams results; official SP+ coefficients are unavailable. | AY34: 6.8861839 | AZ34: 106.88618 | BA34: 28 | BB34: B | BE34: INITIALIZATION ONLY | BF34: 0.0083305699 | BG34: 20 | BH34: 12 | BI34: 12 | BJ34: 0 | BL34: PARTIAL — TOPOLOGY ONLY | BM34: =(F34-'Ensemble Parameters'!$B$20)/'Ensemble Parameters'!$C$20 -> 1.4447275 | BN34: =(L34-'Ensemble Parameters'!$B$21)/'Ensemble Parameters'!$C$21 -> 0.59822666 | BO34: =(S34-'Ensemble Parameters'!$B$22)/'Ensemble Parameters'!$C$22 -> 0.49393652 | BP34: =(W34-'Ensemble Parameters'!$B$23)/'Ensemble Parameters'!$C$23 -> 0.29890244 | BQ34: =AVERAGE(BO34:BP34) -> 0.39641948 | BR34: =(AQ34-'Ensemble Parameters'!$B$24)/'Ensemble Parameters'!$C$24 -> 0.6620743 | BS34: =BM34*'Ensemble Parameters'!$B$5+BN34*'Ensemble Parameters'!$B$6+BQ34*'Ensemble Parameters'!$B$8+BR34*'Ensemble Parameters'!$B$7 -> 0.77536199 | BT34: ='Ensemble Parameters'!$B$11+'Ensemble Parameters'!$B$12*BS34 -> 107.75362 | BU34: ='Ensemble Parameters'!$B$13*BS34 -> 10.855068 | BV34: =RANK(BT34,$BT$5:$BT$125,0) -> 27 | BW34: =STDEV(BM34,BN34,BQ34,BR34) -> 0.46038341 | BX34: =IF(BW34<'Ensemble Parameters'!$B$14,"High",IF(BW34<'Ensemble Parameters'!$B$15,"Moderate","Low")) -> Moderate | BY34: =IF(BX34="Low","REVIEW — MODEL DISAGREEMENT","") | BZ34: 4
